Workbook

Sheet README
A1: Marginal Analysis - farm bed-mix optimization model
A2: Read me / spec for reviewers. Built from capabilities/marginal-analysis/spec.md.
A4: Purpose | B4: Choose non-negative integer numbers of tomato, carrot and mesclun grow beds that maximize seasonal (36-week) farm profit, subject to crop bed caps, the 64-bed farm, and permanent + temporary labor limits. Labor per bed compounds with each crop's own bed count, so the highest-revenue crop (tomato) is not automatically the best to expand.
A6: SHEETS
A7: Summary | B7: One-page optimization summary: recommendation, all required outputs, formula-generated statements of which constraints limit the solution, and the standalone P = MC points.
A8: Inputs | B8: Every case assumption as a named range with unit and source. The only editable cells (yellow, blue text). Two derived inputs (TEMP_HOURS_CAP, TOTAL_LABOR_HOURS_CAP).
A9: Cost Structure | B9: Revenue, fertilizer, crop labor hours, permanent-then-temporary labor allocation, labor dollars, total costs and profit for the current bed mix.
A10: Marginal Cost | B10: Integer q = 0 to each crop's cap: labor hours, fertilizer, and marginal labor hours; marginal labor cost and marginal total cost priced at each crop's MC_RATE (the spec schedule), at the permanent and temporary rates (reference), and permanent hours first (information, spec.md Audit finding A1). Standalone P = MC points and charts of price vs marginal cost.
A11: Optimization | B11: Decision cells (Solver changing cells), objective, constraint checks (green), +1/−1 bed marginal analysis at the current mix, farm-level constraint statements, optimized solution vs enumeration (gold), Solver settings.
A12: Enumeration | B12: Solver-independent proof of the global optimum: profit for every integer mix (21 × 21 × 31 = 13,671), blank where a constraint is broken.
A13: Checks | B13: spec.md Validation Rules V1–V6 (with cells to record Solver and Farm Profit Lab results by hand), then supporting optimum, constraint, error, logic, information and hand-calculation checks.
A15: CONVENTIONS
A16: Yellow fill, blue text | B16: Editable input (Inputs sheet), check tolerance, or result recorded by hand (Checks sheet).
A17: Orange fill, thick red border | B17: Decision cell (Solver changing cell): integer, non-negative.
A18: Green fill | B18: Constraint-check cell.
A19: Gold fill | B19: Recommendation / optimized solution.
A20: Red fill | B20: Excel error, negative or non-integer quantity, or failed check (conditional formatting).
A21: Formulas | B21: Every calculated cell is a formula that refers to named ranges, not hard-coded values. The exceptions are the published check figures and the typed base-case hand calculations on the Checks sheet.
A23: FORMULA DEFINITIONS
A24: LABOR_HOURS(q) | B24: q × HRS_PER_WEEK_PER_BED × SEASON_WEEKS × (1 + DIM_RTRN)^q, per crop with its own parameters. Not linearized. LABOR_HOURS(0) = 0.
A25: Revenue(q) | B25: q × REVENUE_PER_BED; TOTAL_REVENUE = sum over crops.
A26: Fertilizer(q) | B26: q × FERTILIZER_PER_BED; TOTAL_FERTILIZER = sum over crops.
A27: Labor allocation | B27: PERMANENT_HOURS_USED = MIN(TOTAL_LABOR_HOURS, PERMANENT_FIELD_LABOR_HOURS); TEMP_HOURS_USED = MAX(0, TOTAL_LABOR_HOURS − PERMANENT_FIELD_LABOR_HOURS).
A28: Labor cost | B28: PERMANENT_HOURS_USED × PERMANENT_HOURLY_RATE + TEMP_HOURS_USED × TEMP_HOURLY_RATE; BLENDED_LABOR_RATE = TOTAL_LABOR_COST / TOTAL_LABOR_HOURS when hours > 0.
A29: Labor cost by crop | B29: CROP_LABOR_COST = CROP_LABOR_HRS × BLENDED_LABOR_RATE (0 when TOTAL_LABOR_HOURS = 0); the three sum to TOTAL_LABOR_COST. CROP_CONTRIBUTION = CROP_REVENUE − CROP_FERTILIZER − CROP_LABOR_COST. Reporting only.
A30: SEASONAL_PROFIT | B30: TOTAL_REVENUE − TOTAL_FERTILIZER − TOTAL_LABOR_COST − FIXED_SEASON_COST.
A31: Marginal cost | B31: LABOR_COST(q) = LABOR_HOURS(q) × MC_RATE; MARGINAL_LABOR_COST(q) = LABOR_COST(q) − LABOR_COST(q − 1); MARGINAL_COST(q) = MARGINAL_LABOR_COST(q) + FERTILIZER_PER_BED. MC_RATE = TEMP_HOURLY_RATE for tomatoes, PERMANENT_HOURLY_RATE for carrots and mesclun.
A32: Standalone P = MC point | B32: Largest q with REVENUE_PER_BED ≥ MARGINAL_COST(q). A diagnostic only: it ignores the shared labor pool and the 64-bed limit.
A33: Temporary workers required | B33: ROUNDUP(TEMP_HOURS_USED / TEMP_HOURS_LABOR_PER_WORKER, 0); FTE shown alongside. Cost is charged on hours used, per the spec.
A35: SOLVER SETTINGS
A36: Objective | B36: Max OBJECTIVE_SEASONAL_PROFIT (Optimization!C11).
A37: Changing cells | B37: TOMATO_BEDS, CARROT_BEDS, MESCLUN_BEDS (Optimization!C6:C8): integer, non-negative.
A38: Constraints | B38: Each crop's beds ≤ its bed cap; TOTAL_BEDS_USED ≤ TOTAL_BEDS_AVAILABLE; TEMP_HOURS_USED ≤ TEMP_HOURS_CAP; TOTAL_LABOR_HOURS ≤ TOTAL_LABOR_HOURS_CAP. All 64 beds are NOT required to be used.
A39: Method | B39: GRG Nonlinear, Integer Optimality 0%, Make Unconstrained Variables Non-Negative checked. The hidden Solver names on the Optimization sheet pre-load these settings. Run in desktop Excel on 2026-10-13; see Decision cell values below.
A40: Decision cell values | B40: The decision cells hold 10 / 20 / 30. Solver (GRG Nonlinear, integer, Integer Optimality 0%) was run in desktop Excel on 2026-10-13 from 0 / 0 / 0, returning 10 / 20 / 30 and $42,775.16, and from 20 / 0 / 0, returning 10 / 20 / 30 and $42,775.16 ("Solver found a solution" both times). Both runs are recorded on the Checks sheet (V5) and agree with the Enumeration sheet. Checks fails if the decision cells differ from the enumerated optimum.
A42: SPEC DEFECTS FOUND IN THE BUILD (now corrected in spec.md; see its Audit findings)
A43: Labor exponent | B43: spec.md wrote (1 − DIM_RTRN)^q but described labor that increases per added bed. spec.md now writes (1 + DIM_RTRN)^q, which reproduces the 10/20/30 check mix. (1 − DIM_RTRN)^q would give 20/20/24.
A44: Bed-cap constraints | B44: spec.md wrote TOMATO_BEDS ≥ TOMATO_BED_CAP; it now writes ≤ for each crop, as built.
A45: Acceptance mix | B45: spec.md Expected Outputs now names 10/20/30. The brief's 12/20/30 hypothesis is shown on Checks (R1) for reconciliation only.
A46: Profit check | B46: Spec formulas give $42,775.16 vs published $42,762 (+$13.16). Passes V2 within PROFIT_TOLERANCE ($25). The gap is rounding of $34.72, $17.36 and 0.833 (spec.md Audit finding A2).
...

Sheet Summary
A1: Optimization summary - seasonal bed mix
A2: Every value below is a live formula. Re-run Solver after changing an input; the Checks sheet confirms the result.
A4: Recommendation | B4: =RECOMMENDATION_TEXT -> Plant 10 tomato, 20 carrot and 30 mesclun beds (60 of 64 beds) for a seasonal profit of $42,775.
A5: Workbook checks | B5: =CHECKS_OVERALL -> ALL CHECKS PASS
A7: Output | B7: Value | C7: Unit | D7: Named range
A8: Optimized tomato beds | B8: =TOMATO_BEDS -> 10 | C8: beds | D8: TOMATO_BEDS
A9: Optimized carrot beds | B9: =CARROT_BEDS -> 20 | C9: beds | D9: CARROT_BEDS
A10: Optimized mesclun beds | B10: =MESCLUN_BEDS -> 30 | C10: beds | D10: MESCLUN_BEDS
A11: Total beds used | B11: =TOTAL_BEDS_USED -> 60 | C11: beds | D11: TOTAL_BEDS_USED
A12: Unused beds | B12: =UNUSED_BEDS -> 4 | C12: beds | D12: UNUSED_BEDS
A13: Total revenue | B13: =TOTAL_REVENUE -> 210880 | C13: $/season | D13: TOTAL_REVENUE
A14: Total fertilizer cost | B14: =TOTAL_FERTILIZER -> 44000 | C14: $/season | D14: TOTAL_FERTILIZER
A15: Total labor hours | B15: =TOTAL_LABOR_HOURS -> 5276.8228 | C15: hours/season | D15: TOTAL_LABOR_HOURS
A16: Remaining unused labor hours | B16: =UNUSED_LABOR_HOURS -> 1203.1772 | C16: hours/season | D16: UNUSED_LABOR_HOURS
A17: Permanent hours used | B17: =PERMANENT_HOURS_USED -> 720 | C17: hours/season | D17: PERMANENT_HOURS_USED
A18: Temporary hours used | B18: =TEMP_HOURS_USED -> 4556.8228 | C18: hours/season | D18: TEMP_HOURS_USED
A19: Temporary workers required (whole workers) | B19: =TEMP_WORKERS_REQUIRED -> 4 | C19: workers | D19: TEMP_WORKERS_REQUIRED
A20: Temporary workers required (full-time equivalent) | B20: =TEMP_WORKERS_FTE -> 3.1644603 | C20: workers | D20: TEMP_WORKERS_FTE
A21: Total labor cost | B21: =TOTAL_LABOR_COST -> 104104.84 | C21: $/season | D21: TOTAL_LABOR_COST
A22: Blended labor rate | B22: =BLENDED_LABOR_RATE -> 19.728698 | C22: $/hour | D22: BLENDED_LABOR_RATE
A23: Fixed seasonal cost | B23: =FIXED_SEASON_COST -> 20000 | C23: $/season | D23: FIXED_SEASON_COST
A24: Seasonal profit | B24: =SEASONAL_PROFIT -> 42775.155 | C24: $/season | D24: SEASONAL_PROFIT
A26: What limits the optimization
A27: Limit | B27: Statement (formula-generated)
A28: Tomato beds | B28: =TOMATO_LIMIT_STATEMENT -> Not constraint-limited: stops on marginal cost. Bed 11 would add 490 labor hours and change profit by -$590.
A29: Carrot beds | B29: =CARROT_LIMIT_STATEMENT -> BINDING: carrot bed cap (20 beds). One more bed would change profit by $353, so the cap limits profit.
A30: Mesclun beds | B30: =MESCLUN_LIMIT_STATEMENT -> BINDING: mesclun bed cap (30 beds). One more bed would change profit by $247, so the cap limits profit.
A31: Farm beds | B31: =BEDS_LIMIT_STATEMENT -> Not binding: 4 beds unused, so this limit has no opportunity cost at the current mix.
A32: Total labor hours | B32: =LABOR_LIMIT_STATEMENT -> Not binding: 1,203.2 labor hours unused, so this limit has no opportunity cost at the current mix.
A33: Temporary labor hours | B33: =TEMP_LIMIT_STATEMENT -> Not binding: 1,203.2 temporary hours unused, so this limit has no opportunity cost at the current mix.
A34: Permanent labor hours | B34: =PERM_LIMIT_STATEMENT -> Fully used (permanent hours are allocated first). Further hours are bought at the temporary rate of $17.36/hr, which is the marginal labor rate.
A36: Standalone P = MC points (Marginal Cost sheet)
A37: Crop | B37: @ MC_RATE (spec, V3) | C37: Permanent hours first (info) | D37: Bed cap
A38: Tomato | B38: =TOMATO_PMC_Q -> 10 | C38: =TOMATO_PMC_Q_OWNER -> 10 | D38: =TOMATO_BED_CAP -> 20
A39: Carrot | B39: =CARROT_PMC_Q -> 10 | C39: =CARROT_PMC_Q_OWNER -> 20 | D39: =CARROT_BED_CAP -> 20
A40: Mesclun | B40: =MESCLUN_PMC_Q -> 6 | C40: =MESCLUN_PMC_Q_OWNER -> 30 | D40: =MESCLUN_BED_CAP -> 30
A41: MC_RATE: tomatoes at TEMP_HOURLY_RATE, carrots and mesclun at PERMANENT_HOURLY_RATE (spec.md, Calculation Logic). The permanent-hours-first schedule prices labor as SEASONAL_PROFIT does; see spec.md Audit finding A1.
A43: Contribution by crop (labor at the blended rate; reporting only)
A44: Crop | B44: Crop labor cost | C44: Crop contribution | D44: Named ranges
A45: Tomato | B45: =TOMATO_LABOR_COST -> 46054.046 | C45: =TOMATO_CONTRIBUTION -> 33145.954 | D45: TOMATO_LABOR_COST, TOMATO_CONTRIBUTION
...

Sheet Inputs
A1: Inputs - case assumptions
A2: Yellow cells with blue text are the only editable assumptions. Every value is a workbook-level named range. Grey cells are derived formulas.
A4: Name (named range) | B4: Value | C4: Unit | D4: Source | E4: Note
A5: TOMATO_BED_CAP | B5: 20 | C5: beds | D5: Case data, spec.md §Inputs
A6: CARROT_BED_CAP | B6: 20 | C6: beds | D6: Case data, spec.md §Inputs
A7: MESCLUN_BED_CAP | B7: 30 | C7: beds | D7: Case data, spec.md §Inputs
A8: TOMATO_REVENUE_PER_BED | B8: 8800 | C8: $/bed/season | D8: Case data, spec.md §Inputs
A9: CARROT_REVENUE_PER_BED | B9: 2094 | C9: $/bed/season | D9: Case data, spec.md §Inputs
A10: MESCLUN_REVENUE_PER_BED | B10: 2700 | C10: $/bed/season | D10: Case data, spec.md §Inputs
A11: TOMATO_HRS_PER_WEEK_PER_BED | B11: 2.5 | C11: hour/week/bed | D11: Case data, spec.md §Inputs
A12: CARROT_HRS_PER_WEEK_PER_BED | B12: 0.833 | C12: hour/week/bed | D12: Case data, spec.md §Inputs | E12: 5/6 hour (0.8333…) rounded to three decimals; used as published. Effect on profit: spec.md Audit finding A2.
A13: MESCLUN_HRS_PER_WEEK_PER_BED | B13: 1.25 | C13: hour/week/bed | D13: Case data, spec.md §Inputs
A14: TOMATO_FERTILIZER_PER_BED | B14: 880 | C14: $/bed/season | D14: Case data, spec.md §Inputs
A15: CARROT_FERTILIZER_PER_BED | B15: 440 | C15: $/bed/season | D15: Case data, spec.md §Inputs
A16: MESCLUN_FERTILIZER_PER_BED | B16: 880 | C16: $/bed/season | D16: Case data, spec.md §Inputs
A17: TOMATO_DIM_RTRN_PCT | B17: 0.1 | C17: % | D17: Case data, spec.md §Inputs | E17: Spec name TOMATO_DIM_RTRN_% (Excel names cannot contain %). Stored as a decimal: 10% = 0.10.
A18: CARROT_DIM_RTRN_PCT | B18: 0.025 | C18: % | D18: Case data, spec.md §Inputs | E18: Spec name CARROT_DIM_RTRN_%.
A19: MESCLUN_DIM_RTRN_PCT | B19: 0.0125 | C19: % | D19: Case data, spec.md §Inputs | E19: Spec name MESCLUN_DIM_RTRN_%.
A20: SEASON_WEEKS | B20: 36 | C20: weeks | D20: Case data, spec.md §Inputs
A21: TOTAL_BEDS_AVAILABLE | B21: 64 | C21: beds | D21: Case data, spec.md §Inputs
A22: PERMANENT_FIELD_LABOR_HOURS | B22: 720 | C22: hours/season | D22: Case data, spec.md §Inputs | E22: Spec formulas also call this PERMANENT_FIELD_HOURS.
A23: PERMANENT_HOURLY_RATE | B23: 34.72 | C23: $/hour | D23: Case data, spec.md §Inputs | E23: $34.7222… ($25,000 ÷ 720 hours) rounded to the cent; used as published. Effect on profit: spec.md Audit finding A2.
A24: TEMP_WORKER_CAP | B24: 4 | C24: workers | D24: Case data, spec.md §Inputs
A25: TEMP_HOURS_LABOR_PER_WORKER | B25: 1440 | C25: hours/worker/season | D25: Case data, spec.md §Inputs | E25: Spec name TEMP_HOURS_LABOR_PER WORKER (Excel names cannot contain spaces).
A26: TEMP_HOURLY_RATE | B26: 17.36 | C26: $/hour | D26: Case data, spec.md §Inputs | E26: Half the unrounded permanent rate ($17.3611…) rounded to the cent; used as published. Effect on profit: spec.md Audit finding A2.
A27: FIXED_SEASON_COST | B27: 20000 | C27: $/season | D27: Case data, spec.md §Inputs
A29: Derived inputs (formulas - do not edit)
A30: Name (named range) | B30: Value | C30: Unit | D30: Formula | E30: Note
A31: TEMP_HOURS_CAP | B31: =TEMP_HOURS_LABOR_PER_WORKER*TEMP_WORKER_CAP -> 5760 | C31: hours/season | D31: TEMP_HOURS_LABOR_PER_WORKER × TEMP_WORKER_CAP | E31: Spec check value: 5,760 hours
A32: TOTAL_LABOR_HOURS_CAP | B32: =TEMP_HOURS_CAP+PERMANENT_FIELD_LABOR_HOURS -> 6480 | C32: hours/season | D32: TEMP_HOURS_CAP + PERMANENT_FIELD_LABOR_HOURS | E32: Spec check value: 6,480 hours

Sheet Cost Structure
A1: Cost Structure - economics of the current bed mix
A2: Driven by the decision cells on the Optimization sheet. All cells are formulas; named ranges are shown in column A/B.
A4: Crop | B4: Beds | C4: Revenue per bed | D4: Revenue | E4: Fertilizer per bed | F4: Fertilizer | G4: Hours/week/bed | H4: Dim. return | I4: Labor hours | J4: Labor-hours formula
A5: Tomato | B5: =TOMATO_BEDS -> 10 | C5: =TOMATO_REVENUE_PER_BED -> 8800 | D5: =TOMATO_BEDS*TOMATO_REVENUE_PER_BED -> 88000 | E5: =TOMATO_FERTILIZER_PER_BED -> 880 | F5: =TOMATO_BEDS*TOMATO_FERTILIZER_PER_BED -> 8800 | G5: =TOMATO_HRS_PER_WEEK_PER_BED -> 2.5 | H5: =TOMATO_DIM_RTRN_PCT -> 0.1 | I5: =TOMATO_BEDS*TOMATO_HRS_PER_WEEK_PER_BED*SEASON_WEEKS*(1+TOMATO_DIM_RTRN_PCT)^TOMATO_BEDS -> 2334.3682 | J5: TOMATO_BEDS × TOMATO_HRS_PER_WEEK_PER_BED × SEASON_WEEKS × (1 + TOMATO_DIM_RTRN_PCT)^TOMATO_BEDS
A6: Carrot | B6: =CARROT_BEDS -> 20 | C6: =CARROT_REVENUE_PER_BED -> 2094 | D6: =CARROT_BEDS*CARROT_REVENUE_PER_BED -> 41880 | E6: =CARROT_FERTILIZER_PER_BED -> 440 | F6: =CARROT_BEDS*CARROT_FERTILIZER_PER_BED -> 8800 | G6: =CARROT_HRS_PER_WEEK_PER_BED -> 0.833 | H6: =CARROT_DIM_RTRN_PCT -> 0.025 | I6: =CARROT_BEDS*CARROT_HRS_PER_WEEK_PER_BED*SEASON_WEEKS*(1+CARROT_DIM_RTRN_PCT)^CARROT_BEDS -> 982.7766 | J6: CARROT_BEDS × CARROT_HRS_PER_WEEK_PER_BED × SEASON_WEEKS × (1 + CARROT_DIM_RTRN_PCT)^CARROT_BEDS
A7: Mesclun | B7: =MESCLUN_BEDS -> 30 | C7: =MESCLUN_REVENUE_PER_BED -> 2700 | D7: =MESCLUN_BEDS*MESCLUN_REVENUE_PER_BED -> 81000 | E7: =MESCLUN_FERTILIZER_PER_BED -> 880 | F7: =MESCLUN_BEDS*MESCLUN_FERTILIZER_PER_BED -> 26400 | G7: =MESCLUN_HRS_PER_WEEK_PER_BED -> 1.25 | H7: =MESCLUN_DIM_RTRN_PCT -> 0.0125 | I7: =MESCLUN_BEDS*MESCLUN_HRS_PER_WEEK_PER_BED*SEASON_WEEKS*(1+MESCLUN_DIM_RTRN_PCT)^MESCLUN_BEDS -> 1959.678 | J7: MESCLUN_BEDS × MESCLUN_HRS_PER_WEEK_PER_BED × SEASON_WEEKS × (1 + MESCLUN_DIM_RTRN_PCT)^MESCLUN_BEDS
A8: Total | B8: =SUM(B5:B7) -> 60 | D8: =TOMATO_REVENUE+CARROT_REVENUE+MESCLUN_REVENUE -> 210880 | F8: =TOMATO_FERTILIZER+CARROT_FERTILIZER+MESCLUN_FERTILIZER -> 44000 | I8: =TOMATO_LABOR_HRS+CARROT_LABOR_HRS+MESCLUN_LABOR_HRS -> 5276.8228
A11: Labor allocation (permanent hours first, then temporary hours)
A12: Quantity | B12: Named range | C12: Value | D12: Unit | E12: Formula
A13: Total labor hours required | B13: TOTAL_LABOR_HOURS | C13: =TOTAL_LABOR_HOURS -> 5276.8228 | D13: hours | E13: (sum of crop labor hours, above)
A14: Permanent hours used | B14: PERMANENT_HOURS_USED | C14: =MIN(TOTAL_LABOR_HOURS,PERMANENT_FIELD_LABOR_HOURS) -> 720 | D14: hours | E14: MIN(TOTAL_LABOR_HOURS, PERMANENT_FIELD_LABOR_HOURS)
A15: Temporary hours used | B15: TEMP_HOURS_USED | C15: =MAX(0,TOTAL_LABOR_HOURS-PERMANENT_FIELD_LABOR_HOURS) -> 4556.8228 | D15: hours | E15: MAX(0, TOTAL_LABOR_HOURS − PERMANENT_FIELD_LABOR_HOURS)
A16: Permanent labor cost | B16: PERMANENT_LABOR_COST | C16: =PERMANENT_HOURS_USED*PERMANENT_HOURLY_RATE -> 24998.4 | D16: $ | E16: PERMANENT_HOURS_USED × PERMANENT_HOURLY_RATE
A17: Temporary labor cost | B17: TEMP_LABOR_COST | C17: =TEMP_HOURS_USED*TEMP_HOURLY_RATE -> 79106.445 | D17: $ | E17: TEMP_HOURS_USED × TEMP_HOURLY_RATE
A18: Total labor cost | B18: TOTAL_LABOR_COST | C18: =PERMANENT_LABOR_COST+TEMP_LABOR_COST -> 104104.84 | D18: $ | E18: PERMANENT_LABOR_COST + TEMP_LABOR_COST
A19: Blended labor rate | B19: BLENDED_LABOR_RATE | C19: =IF(TOTAL_LABOR_HOURS>0,TOTAL_LABOR_COST/TOTAL_LABOR_HOURS,"n/a - zero labor hours") -> 19.728698 | D19: $/hour | E19: TOTAL_LABOR_COST / TOTAL_LABOR_HOURS, only when TOTAL_LABOR_HOURS > 0 (division-by-zero guard)
A20: Temporary workers required (whole workers) | B20: TEMP_WORKERS_REQUIRED | C20: =ROUNDUP(TEMP_HOURS_USED/TEMP_HOURS_LABOR_PER_WORKER,0) -> 4 | D20: workers | E20: ROUNDUP(TEMP_HOURS_USED / TEMP_HOURS_LABOR_PER_WORKER, 0)
A21: Temporary workers required (full-time equivalent) | B21: TEMP_WORKERS_FTE | C21: =TEMP_HOURS_USED/TEMP_HOURS_LABOR_PER_WORKER -> 3.1644603 | D21: workers | E21: TEMP_HOURS_USED / TEMP_HOURS_LABOR_PER_WORKER
A22: Remaining unused labor hours | B22: UNUSED_LABOR_HOURS | C22: =TOTAL_LABOR_HOURS_CAP-TOTAL_LABOR_HOURS -> 1203.1772 | D22: hours | E22: TOTAL_LABOR_HOURS_CAP − TOTAL_LABOR_HOURS
A23: Unused beds | B23: UNUSED_BEDS | C23: =TOTAL_BEDS_AVAILABLE-TOTAL_BEDS_USED -> 4 | D23: beds | E23: TOTAL_BEDS_AVAILABLE − TOTAL_BEDS_USED
A25: Seasonal profit and loss
A26: Line | B26: Named range | C26: Value | D26: Unit | E26: Formula
A27: Total revenue | B27: TOTAL_REVENUE | C27: =TOTAL_REVENUE -> 210880 | D27: $ | E27: (from crop table)
A28: Less: total fertilizer | B28: TOTAL_FERTILIZER | C28: =-TOTAL_FERTILIZER -> -44000 | D28: $ | E28: (from crop table)
A29: Less: total labor cost | B29: TOTAL_LABOR_COST | C29: =-TOTAL_LABOR_COST -> -104104.84 | D29: $ | E29: (from labor allocation)
A30: Less: fixed season cost | B30: FIXED_SEASON_COST | C30: =-FIXED_SEASON_COST -> -20000 | D30: $ | E30: (input)
A31: Total costs | B31: TOTAL_COSTS | C31: =TOTAL_FERTILIZER+TOTAL_LABOR_COST+FIXED_SEASON_COST -> 168104.84 | D31: $ | E31: TOTAL_FERTILIZER + TOTAL_LABOR_COST + FIXED_SEASON_COST
A32: Seasonal profit | B32: SEASONAL_PROFIT | C32: =TOTAL_REVENUE-TOTAL_FERTILIZER-TOTAL_LABOR_COST-FIXED_SEASON_COST -> 42775.155 | D32: $ | E32: TOTAL_REVENUE − TOTAL_FERTILIZER − TOTAL_LABOR_COST − FIXED_SEASON_COST
A35: Labor cost and contribution by crop (blended labor rate; for reporting only, the optimization uses SEASONAL_PROFIT)
A36: Crop | B36: Labor hours | C36: Blended labor rate | D36: Crop labor cost | E36: Formula | F36: Revenue | G36: Fertilizer | H36: Crop contribution | J36: Named ranges
A37: Tomato | B37: =TOMATO_LABOR_HRS -> 2334.3682 | C37: =IF(TOTAL_LABOR_HOURS>0,BLENDED_LABOR_RATE,0) -> 19.728698 | D37: =IF(TOTAL_LABOR_HOURS>0,TOMATO_LABOR_HRS*BLENDED_LABOR_RATE,0) -> 46054.046 | E37: TOMATO_LABOR_COST = TOMATO_LABOR_HRS × BLENDED_LABOR_RATE (0 when TOTAL_LABOR_HOURS = 0) | F37: =TOMATO_REVENUE -> 88000 | G37: =TOMATO_FERTILIZER -> 8800 | H37: =TOMATO_REVENUE-TOMATO_FERTILIZER-TOMATO_LABOR_COST -> 33145.954 | J37: TOMATO_LABOR_COST, TOMATO_CONTRIBUTION = TOMATO_REVENUE − TOMATO_FERTILIZER − TOMATO_LABOR_COST
A38: Carrot | B38: =CARROT_LABOR_HRS -> 982.7766 | C38: =IF(TOTAL_LABOR_HOURS>0,BLENDED_LABOR_RATE,0) -> 19.728698 | D38: =IF(TOTAL_LABOR_HOURS>0,CARROT_LABOR_HRS*BLENDED_LABOR_RATE,0) -> 19388.903 | E38: CARROT_LABOR_COST = CARROT_LABOR_HRS × BLENDED_LABOR_RATE (0 when TOTAL_LABOR_HOURS = 0) | F38: =CARROT_REVENUE -> 41880 | G38: =CARROT_FERTILIZER -> 8800 | H38: =CARROT_REVENUE-CARROT_FERTILIZER-CARROT_LABOR_COST -> 13691.097 | J38: CARROT_LABOR_COST, CARROT_CONTRIBUTION = CARROT_REVENUE − CARROT_FERTILIZER − CARROT_LABOR_COST
A39: Mesclun | B39: =MESCLUN_LABOR_HRS -> 1959.678 | C39: =IF(TOTAL_LABOR_HOURS>0,BLENDED_LABOR_RATE,0) -> 19.728698 | D39: =IF(TOTAL_LABOR_HOURS>0,MESCLUN_LABOR_HRS*BLENDED_LABOR_RATE,0) -> 38661.896 | E39: MESCLUN_LABOR_COST = MESCLUN_LABOR_HRS × BLENDED_LABOR_RATE (0 when TOTAL_LABOR_HOURS = 0) | F39: =MESCLUN_REVENUE -> 81000 | G39: =MESCLUN_FERTILIZER -> 26400 | H39: =MESCLUN_REVENUE-MESCLUN_FERTILIZER-MESCLUN_LABOR_COST -> 15938.104 | J39: MESCLUN_LABOR_COST, MESCLUN_CONTRIBUTION = MESCLUN_REVENUE − MESCLUN_FERTILIZER − MESCLUN_LABOR_COST
A40: Total | B40: =SUM(B37:B39) -> 5276.8228 | D40: =SUM(D37:D39) -> 104104.84 | E40: Crop labor costs sum to TOTAL_LABOR_COST (tested on Checks, L1) | F40: =SUM(F37:F39) -> 210880 | G40: =SUM(G37:G39) -> 44000 | H40: =SUM(H37:H39) -> 62775.155
A41: Contribution = revenue − fertilizer − labor at the blended rate. It does not include FIXED_SEASON_COST, and it shows each crop's average share of labor cost, not its cost at the margin.

Sheet Marginal Cost
A1: Marginal cost schedules and standalone P = MC diagnostics
A2: Integer q = 0 to each crop's bed cap. The spec schedule (columns O–R) prices each crop at its MC_RATE (spec.md, Calculation Logic): tomatoes at TEMP_HOURLY_RATE, carrots and mesclun at PERMANENT_HOURLY_RATE. Columns C–D and G–N show both single rates for reference. Columns S–V price labor permanent hours first, as SEASONAL_PROFIT does (information only).
A4: Standalone P = MC points (largest q where price ≥ marginal total cost). Each single-rate schedule is priced at one labor rate, so its marginal cost rises with q; the farm's actual labor cost uses permanent hours first (see spec.md Audit finding A1), and that schedule falls where the 720 permanent hours run out: in one step for tomatoes, over two beds for carrots and mesclun.
A5: Crop | B5: Price (revenue per bed) | C5: P = MC point @ permanent rate (beds) | D5: P = MC point @ temporary rate (beds) | E5: Bed cap | F5: MC_RATE ($/hr) | G5: MC_RATE is | H5: P = MC point @ MC_RATE (spec, V3) | I5: P = MC point, permanent hours first (info) | J5: Times MC falls, permanent hours first (info)
A6: Tomato | B6: =TOMATO_REVENUE_PER_BED -> 8800 | C6: =SUMPRODUCT(MAX((M14:M33=1)*A14:A33)) -> 5 | D6: =SUMPRODUCT(MAX((N14:N33=1)*A14:A33)) -> 10 | E6: =TOMATO_BED_CAP -> 20 | F6: =TEMP_HOURLY_RATE -> 17.36 | G6: TEMP_HOURLY_RATE | H6: =SUMPRODUCT(MAX((R14:R33=1)*A14:A33)) -> 10 | I6: =SUMPRODUCT(MAX((V14:V33=1)*A14:A33)) -> 10 | J6: =SUMPRODUCT(--(U15:U33<U14:U32)) -> 1
A7: Carrot | B7: =CARROT_REVENUE_PER_BED -> 2094 | C7: =SUMPRODUCT(MAX((M39:M58=1)*A39:A58)) -> 10 | D7: =SUMPRODUCT(MAX((N39:N58=1)*A39:A58)) -> 20 | E7: =CARROT_BED_CAP -> 20 | F7: =PERMANENT_HOURLY_RATE -> 34.72 | G7: PERMANENT_HOURLY_RATE | H7: =SUMPRODUCT(MAX((R39:R58=1)*A39:A58)) -> 10 | I7: =SUMPRODUCT(MAX((V39:V58=1)*A39:A58)) -> 20 | J7: =SUMPRODUCT(--(U40:U58<U39:U57)) -> 2
A8: Mesclun | B8: =MESCLUN_REVENUE_PER_BED -> 2700 | C8: =SUMPRODUCT(MAX((M64:M93=1)*A64:A93)) -> 6 | D8: =SUMPRODUCT(MAX((N64:N93=1)*A64:A93)) -> 30 | E8: =MESCLUN_BED_CAP -> 30 | F8: =PERMANENT_HOURLY_RATE -> 34.72 | G8: PERMANENT_HOURLY_RATE | H8: =SUMPRODUCT(MAX((R64:R93=1)*A64:A93)) -> 6 | I8: =SUMPRODUCT(MAX((V64:V93=1)*A64:A93)) -> 30 | J8: =SUMPRODUCT(--(U65:U93<U64:U92)) -> 2
A11: Tomato schedule | C11: LABOR_HOURS(q) = q × TOMATO_HRS_PER_WEEK_PER_BED × SEASON_WEEKS × (1 + TOMATO_DIM_RTRN_PCT)^q
A12: q (beds) | B12: Labor hours | C12: Labor $ @ permanent rate | D12: Labor $ @ temp rate | E12: Fertilizer $ | F12: Marginal labor hours | G12: Marginal labor $ @ permanent | H12: Marginal labor $ @ temp | I12: Marginal fertilizer $ | J12: Marginal total cost @ permanent | K12: Marginal total cost @ temp | L12: Price P (revenue/bed) | M12: P ≥ MC @ permanent (1/0) | N12: P ≥ MC @ temp (1/0) | O12: Labor $ @ MC_RATE | P12: Marginal labor $ @ MC_RATE | Q12: Marginal total cost @ MC_RATE (spec) | R12: P ≥ MC @ MC_RATE (1/0) | S12: Labor $, permanent hours first (info) | T12: Marginal labor $, permanent hours first | U12: Marginal total cost, permanent hours first | V12: P ≥ MC, permanent hours first (1/0)
A13: =ROW()-ROW($A$13) -> 0 | B13: =A13*TOMATO_HRS_PER_WEEK_PER_BED*SEASON_WEEKS*(1+TOMATO_DIM_RTRN_PCT)^A13 -> 0 | C13: =B13*PERMANENT_HOURLY_RATE -> 0 | D13: =B13*TEMP_HOURLY_RATE -> 0 | E13: =A13*TOMATO_FERTILIZER_PER_BED -> 0 | F13: — | G13: — | H13: — | I13: — | J13: — | K13: — | L13: =TOMATO_REVENUE_PER_BED -> 8800 | M13: — | N13: — | O13: =B13*TOMATO_MC_RATE -> 0 | P13: — | Q13: — | R13: — | S13: =MIN(B13,PERMANENT_FIELD_LABOR_HOURS)*PERMANENT_HOURLY_RATE+MAX(0,B13-PERMANENT_FIELD_LABOR_HOURS)*TEMP_HOURLY_RATE -> 0 | T13: — | U13: — | V13: —
A14: =ROW()-ROW($A$13) -> 1 | B14: =A14*TOMATO_HRS_PER_WEEK_PER_BED*SEASON_WEEKS*(1+TOMATO_DIM_RTRN_PCT)^A14 -> 99 | C14: =B14*PERMANENT_HOURLY_RATE -> 3437.28 | D14: =B14*TEMP_HOURLY_RATE -> 1718.64 | E14: =A14*TOMATO_FERTILIZER_PER_BED -> 880 | F14: =B14-B13 -> 99 | G14: =C14-C13 -> 3437.28 | H14: =D14-D13 -> 1718.64 | I14: =E14-E13 -> 880 | J14: =G14+I14 -> 4317.28 | K14: =H14+I14 -> 2598.64 | L14: =TOMATO_REVENUE_PER_BED -> 8800 | M14: =IF(L14>=J14,1,0) -> 1 | N14: =IF(L14>=K14,1,0) -> 1 | O14: =B14*TOMATO_MC_RATE -> 1718.64 | P14: =O14-O13 -> 1718.64 | Q14: =P14+I14 -> 2598.64 | R14: =IF(L14>=Q14,1,0) -> 1 | S14: =MIN(B14,PERMANENT_FIELD_LABOR_HOURS)*PERMANENT_HOURLY_RATE+MAX(0,B14-PERMANENT_FIELD_LABOR_HOURS)*TEMP_HOURLY_RATE -> 3437.28 | T14: =S14-S13 -> 3437.28 | U14: =T14+I14 -> 4317.28 | V14: =IF(L14>=U14,1,0) -> 1
A15: =ROW()-ROW($A$13) -> 2 | B15: =A15*TOMATO_HRS_PER_WEEK_PER_BED*SEASON_WEEKS*(1+TOMATO_DIM_RTRN_PCT)^A15 -> 217.8 | C15: =B15*PERMANENT_HOURLY_RATE -> 7562.016 | D15: =B15*TEMP_HOURLY_RATE -> 3781.008 | E15: =A15*TOMATO_FERTILIZER_PER_BED -> 1760 | F15: =B15-B14 -> 118.8 | G15: =C15-C14 -> 4124.736 | H15: =D15-D14 -> 2062.368 | I15: =E15-E14 -> 880 | J15: =G15+I15 -> 5004.736 | K15: =H15+I15 -> 2942.368 | L15: =TOMATO_REVENUE_PER_BED -> 8800 | M15: =IF(L15>=J15,1,0) -> 1 | N15: =IF(L15>=K15,1,0) -> 1 | O15: =B15*TOMATO_MC_RATE -> 3781.008 | P15: =O15-O14 -> 2062.368 | Q15: =P15+I15 -> 2942.368 | R15: =IF(L15>=Q15,1,0) -> 1 | S15: =MIN(B15,PERMANENT_FIELD_LABOR_HOURS)*PERMANENT_HOURLY_RATE+MAX(0,B15-PERMANENT_FIELD_LABOR_HOURS)*TEMP_HOURLY_RATE -> 7562.016 | T15: =S15-S14 -> 4124.736 | U15: =T15+I15 -> 5004.736 | V15: =IF(L15>=U15,1,0) -> 1
A16: =ROW()-ROW($A$13) -> 3 | B16: =A16*TOMATO_HRS_PER_WEEK_PER_BED*SEASON_WEEKS*(1+TOMATO_DIM_RTRN_PCT)^A16 -> 359.37 | C16: =B16*PERMANENT_HOURLY_RATE -> 12477.326 | D16: =B16*TEMP_HOURLY_RATE -> 6238.6632 | E16: =A16*TOMATO_FERTILIZER_PER_BED -> 2640 | F16: =B16-B15 -> 141.57 | G16: =C16-C15 -> 4915.3104 | H16: =D16-D15 -> 2457.6552 | I16: =E16-E15 -> 880 | J16: =G16+I16 -> 5795.3104 | K16: =H16+I16 -> 3337.6552 | L16: =TOMATO_REVENUE_PER_BED -> 8800 | M16: =IF(L16>=J16,1,0) -> 1 | N16: =IF(L16>=K16,1,0) -> 1 | O16: =B16*TOMATO_MC_RATE -> 6238.6632 | P16: =O16-O15 -> 2457.6552 | Q16: =P16+I16 -> 3337.6552 | R16: =IF(L16>=Q16,1,0) -> 1 | S16: =MIN(B16,PERMANENT_FIELD_LABOR_HOURS)*PERMANENT_HOURLY_RATE+MAX(0,B16-PERMANENT_FIELD_LABOR_HOURS)*TEMP_HOURLY_RATE -> 12477.326 | T16: =S16-S15 -> 4915.3104 | U16: =T16+I16 -> 5795.3104 | V16: =IF(L16>=U16,1,0) -> 1
A17: =ROW()-ROW($A$13) -> 4 | B17: =A17*TOMATO_HRS_PER_WEEK_PER_BED*SEASON_WEEKS*(1+TOMATO_DIM_RTRN_PCT)^A17 -> 527.076 | C17: =B17*PERMANENT_HOURLY_RATE -> 18300.079 | D17: =B17*TEMP_HOURLY_RATE -> 9150.0394 | E17: =A17*TOMATO_FERTILIZER_PER_BED -> 3520 | F17: =B17-B16 -> 167.706 | G17: =C17-C16 -> 5822.7523 | H17: =D17-D16 -> 2911.3762 | I17: =E17-E16 -> 880 | J17: =G17+I17 -> 6702.7523 | K17: =H17+I17 -> 3791.3762 | L17: =TOMATO_REVENUE_PER_BED -> 8800 | M17: =IF(L17>=J17,1,0) -> 1 | N17: =IF(L17>=K17,1,0) -> 1 | O17: =B17*TOMATO_MC_RATE -> 9150.0394 | P17: =O17-O16 -> 2911.3762 | Q17: =P17+I17 -> 3791.3762 | R17: =IF(L17>=Q17,1,0) -> 1 | S17: =MIN(B17,PERMANENT_FIELD_LABOR_HOURS)*PERMANENT_HOURLY_RATE+MAX(0,B17-PERMANENT_FIELD_LABOR_HOURS)*TEMP_HOURLY_RATE -> 18300.079 | T17: =S17-S16 -> 5822.7523 | U17: =T17+I17 -> 6702.7523 | V17: =IF(L17>=U17,1,0) -> 1
A18: =ROW()-ROW($A$13) -> 5 | B18: =A18*TOMATO_HRS_PER_WEEK_PER_BED*SEASON_WEEKS*(1+TOMATO_DIM_RTRN_PCT)^A18 -> 724.7295 | C18: =B18*PERMANENT_HOURLY_RATE -> 25162.608 | D18: =B18*TEMP_HOURLY_RATE -> 12581.304 | E18: =A18*TOMATO_FERTILIZER_PER_BED -> 4400 | F18: =B18-B17 -> 197.6535 | G18: =C18-C17 -> 6862.5295 | H18: =D18-D17 -> 3431.2648 | I18: =E18-E17 -> 880 | J18: =G18+I18 -> 7742.5295 | K18: =H18+I18 -> 4311.2648 | L18: =TOMATO_REVENUE_PER_BED -> 8800 | M18: =IF(L18>=J18,1,0) -> 1 | N18: =IF(L18>=K18,1,0) -> 1 | O18: =B18*TOMATO_MC_RATE -> 12581.304 | P18: =O18-O17 -> 3431.2648 | Q18: =P18+I18 -> 4311.2648 | R18: =IF(L18>=Q18,1,0) -> 1 | S18: =MIN(B18,PERMANENT_FIELD_LABOR_HOURS)*PERMANENT_HOURLY_RATE+MAX(0,B18-PERMANENT_FIELD_LABOR_HOURS)*TEMP_HOURLY_RATE -> 25080.504 | T18: =S18-S17 -> 6780.4254 | U18: =T18+I18 -> 7660.4254 | V18: =IF(L18>=U18,1,0) -> 1
A19: =ROW()-ROW($A$13) -> 6 | B19: =A19*TOMATO_HRS_PER_WEEK_PER_BED*SEASON_WEEKS*(1+TOMATO_DIM_RTRN_PCT)^A19 -> 956.64294 | C19: =B19*PERMANENT_HOURLY_RATE -> 33214.643 | D19: =B19*TEMP_HOURLY_RATE -> 16607.321 | E19: =A19*TOMATO_FERTILIZER_PER_BED -> 5280 | F19: =B19-B18 -> 231.91344 | G19: =C19-C18 -> 8052.0346 | H19: =D19-D18 -> 4026.0173 | I19: =E19-E18 -> 880 | J19: =G19+I19 -> 8932.0346 | K19: =H19+I19 -> 4906.0173 | L19: =TOMATO_REVENUE_PER_BED -> 8800 | M19: =IF(L19>=J19,1,0) -> 0 | N19: =IF(L19>=K19,1,0) -> 1 | O19: =B19*TOMATO_MC_RATE -> 16607.321 | P19: =O19-O18 -> 4026.0173 | Q19: =P19+I19 -> 4906.0173 | R19: =IF(L19>=Q19,1,0) -> 1 | S19: =MIN(B19,PERMANENT_FIELD_LABOR_HOURS)*PERMANENT_HOURLY_RATE+MAX(0,B19-PERMANENT_FIELD_LABOR_HOURS)*TEMP_HOURLY_RATE -> 29106.521 | T19: =S19-S18 -> 4026.0173 | U19: =T19+I19 -> 4906.0173 | V19: =IF(L19>=U19,1,0) -> 1
A20: =ROW()-ROW($A$13) -> 7 | B20: =A20*TOMATO_HRS_PER_WEEK_PER_BED*SEASON_WEEKS*(1+TOMATO_DIM_RTRN_PCT)^A20 -> 1227.6918 | C20: =B20*PERMANENT_HOURLY_RATE -> 42625.458 | D20: =B20*TEMP_HOURLY_RATE -> 21312.729 | E20: =A20*TOMATO_FERTILIZER_PER_BED -> 6160 | F20: =B20-B19 -> 271.04883 | G20: =C20-C19 -> 9410.8155 | H20: =D20-D19 -> 4705.4077 | I20: =E20-E19 -> 880 | J20: =G20+I20 -> 10290.815 | K20: =H20+I20 -> 5585.4077 | L20: =TOMATO_REVENUE_PER_BED -> 8800 | M20: =IF(L20>=J20,1,0) -> 0 | N20: =IF(L20>=K20,1,0) -> 1 | O20: =B20*TOMATO_MC_RATE -> 21312.729 | P20: =O20-O19 -> 4705.4077 | Q20: =P20+I20 -> 5585.4077 | R20: =IF(L20>=Q20,1,0) -> 1 | S20: =MIN(B20,PERMANENT_FIELD_LABOR_HOURS)*PERMANENT_HOURLY_RATE+MAX(0,B20-PERMANENT_FIELD_LABOR_HOURS)*TEMP_HOURLY_RATE -> 33811.929 | T20: =S20-S19 -> 4705.4077 | U20: =T20+I20 -> 5585.4077 | V20: =IF(L20>=U20,1,0) -> 1
A21: =ROW()-ROW($A$13) -> 8 | B21: =A21*TOMATO_HRS_PER_WEEK_PER_BED*SEASON_WEEKS*(1+TOMATO_DIM_RTRN_PCT)^A21 -> 1543.3839 | C21: =B21*PERMANENT_HOURLY_RATE -> 53586.291 | D21: =B21*TEMP_HOURLY_RATE -> 26793.145 | E21: =A21*TOMATO_FERTILIZER_PER_BED -> 7040 | F21: =B21-B20 -> 315.69217 | G21: =C21-C20 -> 10960.832 | H21: =D21-D20 -> 5480.4161 | I21: =E21-E20 -> 880 | J21: =G21+I21 -> 11840.832 | K21: =H21+I21 -> 6360.4161 | L21: =TOMATO_REVENUE_PER_BED -> 8800 | M21: =IF(L21>=J21,1,0) -> 0 | N21: =IF(L21>=K21,1,0) -> 1 | O21: =B21*TOMATO_MC_RATE -> 26793.145 | P21: =O21-O20 -> 5480.4161 | Q21: =P21+I21 -> 6360.4161 | R21: =IF(L21>=Q21,1,0) -> 1 | S21: =MIN(B21,PERMANENT_FIELD_LABOR_HOURS)*PERMANENT_HOURLY_RATE+MAX(0,B21-PERMANENT_FIELD_LABOR_HOURS)*TEMP_HOURLY_RATE -> 39292.345 | T21: =S21-S20 -> 5480.4161 | U21: =T21+I21 -> 6360.4161 | V21: =IF(L21>=U21,1,0) -> 1
A22: =ROW()-ROW($A$13) -> 9 | B22: =A22*TOMATO_HRS_PER_WEEK_PER_BED*SEASON_WEEKS*(1+TOMATO_DIM_RTRN_PCT)^A22 -> 1909.9376 | C22: =B22*PERMANENT_HOURLY_RATE -> 66313.035 | D22: =B22*TEMP_HOURLY_RATE -> 33156.517 | E22: =A22*TOMATO_FERTILIZER_PER_BED -> 7920 | F22: =B22-B21 -> 366.55369 | G22: =C22-C21 -> 12726.744 | H22: =D22-D21 -> 6363.372 | I22: =E22-E21 -> 880 | J22: =G22+I22 -> 13606.744 | K22: =H22+I22 -> 7243.372 | L22: =TOMATO_REVENUE_PER_BED -> 8800 | M22: =IF(L22>=J22,1,0) -> 0 | N22: =IF(L22>=K22,1,0) -> 1 | O22: =B22*TOMATO_MC_RATE -> 33156.517 | P22: =O22-O21 -> 6363.372 | Q22: =P22+I22 -> 7243.372 | R22: =IF(L22>=Q22,1,0) -> 1 | S22: =MIN(B22,PERMANENT_FIELD_LABOR_HOURS)*PERMANENT_HOURLY_RATE+MAX(0,B22-PERMANENT_FIELD_LABOR_HOURS)*TEMP_HOURLY_RATE -> 45655.717 | T22: =S22-S21 -> 6363.372 | U22: =T22+I22 -> 7243.372 | V22: =IF(L22>=U22,1,0) -> 1
A23: =ROW()-ROW($A$13) -> 10 | B23: =A23*TOMATO_HRS_PER_WEEK_PER_BED*SEASON_WEEKS*(1+TOMATO_DIM_RTRN_PCT)^A23 -> 2334.3682 | C23: =B23*PERMANENT_HOURLY_RATE -> 81049.264 | D23: =B23*TEMP_HOURLY_RATE -> 40524.632 | E23: =A23*TOMATO_FERTILIZER_PER_BED -> 8800 | F23: =B23-B22 -> 424.43058 | G23: =C23-C22 -> 14736.23 | H23: =D23-D22 -> 7368.1149 | I23: =E23-E22 -> 880 | J23: =G23+I23 -> 15616.23 | K23: =H23+I23 -> 8248.1149 | L23: =TOMATO_REVENUE_PER_BED -> 8800 | M23: =IF(L23>=J23,1,0) -> 0 | N23: =IF(L23>=K23,1,0) -> 1 | O23: =B23*TOMATO_MC_RATE -> 40524.632 | P23: =O23-O22 -> 7368.1149 | Q23: =P23+I23 -> 8248.1149 | R23: =IF(L23>=Q23,1,0) -> 1 | S23: =MIN(B23,PERMANENT_FIELD_LABOR_HOURS)*PERMANENT_HOURLY_RATE+MAX(0,B23-PERMANENT_FIELD_LABOR_HOURS)*TEMP_HOURLY_RATE -> 53023.832 | T23: =S23-S22 -> 7368.1149 | U23: =T23+I23 -> 8248.1149 | V23: =IF(L23>=U23,1,0) -> 1
A24: =ROW()-ROW($A$13) -> 11 | B24: =A24*TOMATO_HRS_PER_WEEK_PER_BED*SEASON_WEEKS*(1+TOMATO_DIM_RTRN_PCT)^A24 -> 2824.5855 | C24: =B24*PERMANENT_HOURLY_RATE -> 98069.61 | D24: =B24*TEMP_HOURLY_RATE -> 49034.805 | E24: =A24*TOMATO_FERTILIZER_PER_BED -> 9680 | F24: =B24-B23 -> 490.21732 | G24: =C24-C23 -> 17020.346 | H24: =D24-D23 -> 8510.1728 | I24: =E24-E23 -> 880 | J24: =G24+I24 -> 17900.346 | K24: =H24+I24 -> 9390.1728 | L24: =TOMATO_REVENUE_PER_BED -> 8800 | M24: =IF(L24>=J24,1,0) -> 0 | N24: =IF(L24>=K24,1,0) -> 0 | O24: =B24*TOMATO_MC_RATE -> 49034.805 | P24: =O24-O23 -> 8510.1728 | Q24: =P24+I24 -> 9390.1728 | R24: =IF(L24>=Q24,1,0) -> 0 | S24: =MIN(B24,PERMANENT_FIELD_LABOR_HOURS)*PERMANENT_HOURLY_RATE+MAX(0,B24-PERMANENT_FIELD_LABOR_HOURS)*TEMP_HOURLY_RATE -> 61534.005 | T24: =S24-S23 -> 8510.1728 | U24: =T24+I24 -> 9390.1728 | V24: =IF(L24>=U24,1,0) -> 0
A25: =ROW()-ROW($A$13) -> 12 | B25: =A25*TOMATO_HRS_PER_WEEK_PER_BED*SEASON_WEEKS*(1+TOMATO_DIM_RTRN_PCT)^A25 -> 3389.5026 | C25: =B25*PERMANENT_HOURLY_RATE -> 117683.53 | D25: =B25*TEMP_HOURLY_RATE -> 58841.766 | E25: =A25*TOMATO_FERTILIZER_PER_BED -> 10560 | F25: =B25-B24 -> 564.91711 | G25: =C25-C24 -> 19613.922 | H25: =D25-D24 -> 9806.961 | I25: =E25-E24 -> 880 | J25: =G25+I25 -> 20493.922 | K25: =H25+I25 -> 10686.961 | L25: =TOMATO_REVENUE_PER_BED -> 8800 | M25: =IF(L25>=J25,1,0) -> 0 | N25: =IF(L25>=K25,1,0) -> 0 | O25: =B25*TOMATO_MC_RATE -> 58841.766 | P25: =O25-O24 -> 9806.961 | Q25: =P25+I25 -> 10686.961 | R25: =IF(L25>=Q25,1,0) -> 0 | S25: =MIN(B25,PERMANENT_FIELD_LABOR_HOURS)*PERMANENT_HOURLY_RATE+MAX(0,B25-PERMANENT_FIELD_LABOR_HOURS)*TEMP_HOURLY_RATE -> 71340.966 | T25: =S25-S24 -> 9806.961 | U25: =T25+I25 -> 10686.961 | V25: =IF(L25>=U25,1,0) -> 0
... A33: =ROW()-ROW($A$13) -> 20 | B33: =A33*TOMATO_HRS_PER_WEEK_PER_BED*SEASON_WEEKS*(1+TOMATO_DIM_RTRN_PCT)^A33 -> 12109.5 | C33: =B33*PERMANENT_HOURLY_RATE -> 420441.84 | D33: =B33*TEMP_HOURLY_RATE -> 210220.92 | E33: =A33*TOMATO_FERTILIZER_PER_BED -> 17600 | F33: =B33-B32 -> 1651.2954 | G33: =C33-C32 -> 57332.978 | H33: =D33-D32 -> 28666.489 | I33: =E33-E32 -> 880 | J33: =G33+I33 -> 58212.978 | K33: =H33+I33 -> 29546.489 | L33: =TOMATO_REVENUE_PER_BED -> 8800 | M33: =IF(L33>=J33,1,0) -> 0 | N33: =IF(L33>=K33,1,0) -> 0 | O33: =B33*TOMATO_MC_RATE -> 210220.92 | P33: =O33-O32 -> 28666.489 | Q33: =P33+I33 -> 29546.489 | R33: =IF(L33>=Q33,1,0) -> 0 | S33: =MIN(B33,PERMANENT_FIELD_LABOR_HOURS)*PERMANENT_HOURLY_RATE+MAX(0,B33-PERMANENT_FIELD_LABOR_HOURS)*TEMP_HOURLY_RATE -> 222720.12 | T33: =S33-S32 -> 28666.489 | U33: =T33+I33 -> 29546.489 | V33: =IF(L33>=U33,1,0) -> 0
A36: Carrot schedule | C36: LABOR_HOURS(q) = q × CARROT_HRS_PER_WEEK_PER_BED × SEASON_WEEKS × (1 + CARROT_DIM_RTRN_PCT)^q
A37: q (beds) | B37: Labor hours | C37: Labor $ @ permanent rate | D37: Labor $ @ temp rate | E37: Fertilizer $ | F37: Marginal labor hours | G37: Marginal labor $ @ permanent | H37: Marginal labor $ @ temp | I37: Marginal fertilizer $ | J37: Marginal total cost @ permanent | K37: Marginal total cost @ temp | L37: Price P (revenue/bed) | M37: P ≥ MC @ permanent (1/0) | N37: P ≥ MC @ temp (1/0) | O37: Labor $ @ MC_RATE | P37: Marginal labor $ @ MC_RATE | Q37: Marginal total cost @ MC_RATE (spec) | R37: P ≥ MC @ MC_RATE (1/0) | S37: Labor $, permanent hours first (info) | T37: Marginal labor $, permanent hours first | U37: Marginal total cost, permanent hours first | V37: P ≥ MC, permanent hours first (1/0)
A38: =ROW()-ROW($A$38) -> 0 | B38: =A38*CARROT_HRS_PER_WEEK_PER_BED*SEASON_WEEKS*(1+CARROT_DIM_RTRN_PCT)^A38 -> 0 | C38: =B38*PERMANENT_HOURLY_RATE -> 0 | D38: =B38*TEMP_HOURLY_RATE -> 0 | E38: =A38*CARROT_FERTILIZER_PER_BED -> 0 | F38: — | G38: — | H38: — | I38: — | J38: — | K38: — | L38: =CARROT_REVENUE_PER_BED -> 2094 | M38: — | N38: — | O38: =B38*CARROT_MC_RATE -> 0 | P38: — | Q38: — | R38: — | S38: =MIN(B38,PERMANENT_FIELD_LABOR_HOURS)*PERMANENT_HOURLY_RATE+MAX(0,B38-PERMANENT_FIELD_LABOR_HOURS)*TEMP_HOURLY_RATE -> 0 | T38: — | U38: — | V38: —
A39: =ROW()-ROW($A$38) -> 1 | B39: =A39*CARROT_HRS_PER_WEEK_PER_BED*SEASON_WEEKS*(1+CARROT_DIM_RTRN_PCT)^A39 -> 30.7377 | C39: =B39*PERMANENT_HOURLY_RATE -> 1067.2129 | D39: =B39*TEMP_HOURLY_RATE -> 533.60647 | E39: =A39*CARROT_FERTILIZER_PER_BED -> 440 | F39: =B39-B38 -> 30.7377 | G39: =C39-C38 -> 1067.2129 | H39: =D39-D38 -> 533.60647 | I39: =E39-E38 -> 440 | J39: =G39+I39 -> 1507.2129 | K39: =H39+I39 -> 973.60647 | L39: =CARROT_REVENUE_PER_BED -> 2094 | M39: =IF(L39>=J39,1,0) -> 1 | N39: =IF(L39>=K39,1,0) -> 1 | O39: =B39*CARROT_MC_RATE -> 1067.2129 | P39: =O39-O38 -> 1067.2129 | Q39: =P39+I39 -> 1507.2129 | R39: =IF(L39>=Q39,1,0) -> 1 | S39: =MIN(B39,PERMANENT_FIELD_LABOR_HOURS)*PERMANENT_HOURLY_RATE+MAX(0,B39-PERMANENT_FIELD_LABOR_HOURS)*TEMP_HOURLY_RATE -> 1067.2129 | T39: =S39-S38 -> 1067.2129 | U39: =T39+I39 -> 1507.2129 | V39: =IF(L39>=U39,1,0) -> 1
A40: =ROW()-ROW($A$38) -> 2 | B40: =A40*CARROT_HRS_PER_WEEK_PER_BED*SEASON_WEEKS*(1+CARROT_DIM_RTRN_PCT)^A40 -> 63.012285 | C40: =B40*PERMANENT_HOURLY_RATE -> 2187.7865 | D40: =B40*TEMP_HOURLY_RATE -> 1093.8933 | E40: =A40*CARROT_FERTILIZER_PER_BED -> 880 | F40: =B40-B39 -> 32.274585 | G40: =C40-C39 -> 1120.5736 | H40: =D40-D39 -> 560.2868 | I40: =E40-E39 -> 440 | J40: =G40+I40 -> 1560.5736 | K40: =H40+I40 -> 1000.2868 | L40: =CARROT_REVENUE_PER_BED -> 2094 | M40: =IF(L40>=J40,1,0) -> 1 | N40: =IF(L40>=K40,1,0) -> 1 | O40: =B40*CARROT_MC_RATE -> 2187.7865 | P40: =O40-O39 -> 1120.5736 | Q40: =P40+I40 -> 1560.5736 | R40: =IF(L40>=Q40,1,0) -> 1 | S40: =MIN(B40,PERMANENT_FIELD_LABOR_HOURS)*PERMANENT_HOURLY_RATE+MAX(0,B40-PERMANENT_FIELD_LABOR_HOURS)*TEMP_HOURLY_RATE -> 2187.7865 | T40: =S40-S39 -> 1120.5736 | U40: =T40+I40 -> 1560.5736 | V40: =IF(L40>=U40,1,0) -> 1
A41: =ROW()-ROW($A$38) -> 3 | B41: =A41*CARROT_HRS_PER_WEEK_PER_BED*SEASON_WEEKS*(1+CARROT_DIM_RTRN_PCT)^A41 -> 96.881388 | C41: =B41*PERMANENT_HOURLY_RATE -> 3363.7218 | D41: =B41*TEMP_HOURLY_RATE -> 1681.8609 | E41: =A41*CARROT_FERTILIZER_PER_BED -> 1320 | F41: =B41-B40 -> 33.869103 | G41: =C41-C40 -> 1175.9353 | H41: =D41-D40 -> 587.96763 | I41: =E41-E40 -> 440 | J41: =G41+I41 -> 1615.9353 | K41: =H41+I41 -> 1027.9676 | L41: =CARROT_REVENUE_PER_BED -> 2094 | M41: =IF(L41>=J41,1,0) -> 1 | N41: =IF(L41>=K41,1,0) -> 1 | O41: =B41*CARROT_MC_RATE -> 3363.7218 | P41: =O41-O40 -> 1175.9353 | Q41: =P41+I41 -> 1615.9353 | R41: =IF(L41>=Q41,1,0) -> 1 | S41: =MIN(B41,PERMANENT_FIELD_LABOR_HOURS)*PERMANENT_HOURLY_RATE+MAX(0,B41-PERMANENT_FIELD_LABOR_HOURS)*TEMP_HOURLY_RATE -> 3363.7218 | T41: =S41-S40 -> 1175.9353 | U41: =T41+I41 -> 1615.9353 | V41: =IF(L41>=U41,1,0) -> 1
A42: =ROW()-ROW($A$38) -> 4 | B42: =A42*CARROT_HRS_PER_WEEK_PER_BED*SEASON_WEEKS*(1+CARROT_DIM_RTRN_PCT)^A42 -> 132.40456 | C42: =B42*PERMANENT_HOURLY_RATE -> 4597.0865 | D42: =B42*TEMP_HOURLY_RATE -> 2298.5432 | E42: =A42*CARROT_FERTILIZER_PER_BED -> 1760 | F42: =B42-B41 -> 35.523176 | G42: =C42-C41 -> 1233.3647 | H42: =D42-D41 -> 616.68233 | I42: =E42-E41 -> 440 | J42: =G42+I42 -> 1673.3647 | K42: =H42+I42 -> 1056.6823 | L42: =CARROT_REVENUE_PER_BED -> 2094 | M42: =IF(L42>=J42,1,0) -> 1 | N42: =IF(L42>=K42,1,0) -> 1 | O42: =B42*CARROT_MC_RATE -> 4597.0865 | P42: =O42-O41 -> 1233.3647 | Q42: =P42+I42 -> 1673.3647 | R42: =IF(L42>=Q42,1,0) -> 1 | S42: =MIN(B42,PERMANENT_FIELD_LABOR_HOURS)*PERMANENT_HOURLY_RATE+MAX(0,B42-PERMANENT_FIELD_LABOR_HOURS)*TEMP_HOURLY_RATE -> 4597.0865 | T42: =S42-S41 -> 1233.3647 | U42: =T42+I42 -> 1673.3647 | V42: =IF(L42>=U42,1,0) -> 1
A43: =ROW()-ROW($A$38) -> 5 | B43: =A43*CARROT_HRS_PER_WEEK_PER_BED*SEASON_WEEKS*(1+CARROT_DIM_RTRN_PCT)^A43 -> 169.64335 | C43: =B43*PERMANENT_HOURLY_RATE -> 5890.017 | D43: =B43*TEMP_HOURLY_RATE -> 2945.0085 | E43: =A43*CARROT_FERTILIZER_PER_BED -> 2200 | F43: =B43-B42 -> 37.238784 | G43: =C43-C42 -> 1292.9306 | H43: =D43-D42 -> 646.46528 | I43: =E43-E42 -> 440 | J43: =G43+I43 -> 1732.9306 | K43: =H43+I43 -> 1086.4653 | L43: =CARROT_REVENUE_PER_BED -> 2094 | M43: =IF(L43>=J43,1,0) -> 1 | N43: =IF(L43>=K43,1,0) -> 1 | O43: =B43*CARROT_MC_RATE -> 5890.017 | P43: =O43-O42 -> 1292.9306 | Q43: =P43+I43 -> 1732.9306 | R43: =IF(L43>=Q43,1,0) -> 1 | S43: =MIN(B43,PERMANENT_FIELD_LABOR_HOURS)*PERMANENT_HOURLY_RATE+MAX(0,B43-PERMANENT_FIELD_LABOR_HOURS)*TEMP_HOURLY_RATE -> 5890.017 | T43: =S43-S42 -> 1292.9306 | U43: =T43+I43 -> 1732.9306 | V43: =IF(L43>=U43,1,0) -> 1
A44: =ROW()-ROW($A$38) -> 6 | B44: =A44*CARROT_HRS_PER_WEEK_PER_BED*SEASON_WEEKS*(1+CARROT_DIM_RTRN_PCT)^A44 -> 208.66132 | C44: =B44*PERMANENT_HOURLY_RATE -> 7244.7209 | D44: =B44*TEMP_HOURLY_RATE -> 3622.3605 | E44: =A44*CARROT_FERTILIZER_PER_BED -> 2640 | F44: =B44-B43 -> 39.01797 | G44: =C44-C43 -> 1354.7039 | H44: =D44-D43 -> 677.35196 | I44: =E44-E43 -> 440 | J44: =G44+I44 -> 1794.7039 | K44: =H44+I44 -> 1117.352 | L44: =CARROT_REVENUE_PER_BED -> 2094 | M44: =IF(L44>=J44,1,0) -> 1 | N44: =IF(L44>=K44,1,0) -> 1 | O44: =B44*CARROT_MC_RATE -> 7244.7209 | P44: =O44-O43 -> 1354.7039 | Q44: =P44+I44 -> 1794.7039 | R44: =IF(L44>=Q44,1,0) -> 1 | S44: =MIN(B44,PERMANENT_FIELD_LABOR_HOURS)*PERMANENT_HOURLY_RATE+MAX(0,B44-PERMANENT_FIELD_LABOR_HOURS)*TEMP_HOURLY_RATE -> 7244.7209 | T44: =S44-S43 -> 1354.7039 | U44: =T44+I44 -> 1794.7039 | V44: =IF(L44>=U44,1,0) -> 1
A45: =ROW()-ROW($A$38) -> 7 | B45: =A45*CARROT_HRS_PER_WEEK_PER_BED*SEASON_WEEKS*(1+CARROT_DIM_RTRN_PCT)^A45 -> 249.52416 | C45: =B45*PERMANENT_HOURLY_RATE -> 8663.4788 | D45: =B45*TEMP_HOURLY_RATE -> 4331.7394 | E45: =A45*CARROT_FERTILIZER_PER_BED -> 3080 | F45: =B45-B44 -> 40.862841 | G45: =C45-C44 -> 1418.7579 | H45: =D45-D44 -> 709.37893 | I45: =E45-E44 -> 440 | J45: =G45+I45 -> 1858.7579 | K45: =H45+I45 -> 1149.3789 | L45: =CARROT_REVENUE_PER_BED -> 2094 | M45: =IF(L45>=J45,1,0) -> 1 | N45: =IF(L45>=K45,1,0) -> 1 | O45: =B45*CARROT_MC_RATE -> 8663.4788 | P45: =O45-O44 -> 1418.7579 | Q45: =P45+I45 -> 1858.7579 | R45: =IF(L45>=Q45,1,0) -> 1 | S45: =MIN(B45,PERMANENT_FIELD_LABOR_HOURS)*PERMANENT_HOURLY_RATE+MAX(0,B45-PERMANENT_FIELD_LABOR_HOURS)*TEMP_HOURLY_RATE -> 8663.4788 | T45: =S45-S44 -> 1418.7579 | U45: =T45+I45 -> 1858.7579 | V45: =IF(L45>=U45,1,0) -> 1
A46: =ROW()-ROW($A$38) -> 8 | B46: =A46*CARROT_HRS_PER_WEEK_PER_BED*SEASON_WEEKS*(1+CARROT_DIM_RTRN_PCT)^A46 -> 292.29973 | C46: =B46*PERMANENT_HOURLY_RATE -> 10148.647 | D46: =B46*TEMP_HOURLY_RATE -> 5074.3233 | E46: =A46*CARROT_FERTILIZER_PER_BED -> 3520 | F46: =B46-B45 -> 42.77557 | G46: =C46-C45 -> 1485.1678 | H46: =D46-D45 -> 742.5839 | I46: =E46-E45 -> 440 | J46: =G46+I46 -> 1925.1678 | K46: =H46+I46 -> 1182.5839 | L46: =CARROT_REVENUE_PER_BED -> 2094 | M46: =IF(L46>=J46,1,0) -> 1 | N46: =IF(L46>=K46,1,0) -> 1 | O46: =B46*CARROT_MC_RATE -> 10148.647 | P46: =O46-O45 -> 1485.1678 | Q46: =P46+I46 -> 1925.1678 | R46: =IF(L46>=Q46,1,0) -> 1 | S46: =MIN(B46,PERMANENT_FIELD_LABOR_HOURS)*PERMANENT_HOURLY_RATE+MAX(0,B46-PERMANENT_FIELD_LABOR_HOURS)*TEMP_HOURLY_RATE -> 10148.647 | T46: =S46-S45 -> 1485.1678 | U46: =T46+I46 -> 1925.1678 | V46: =IF(L46>=U46,1,0) -> 1
A47: =ROW()-ROW($A$38) -> 9 | B47: =A47*CARROT_HRS_PER_WEEK_PER_BED*SEASON_WEEKS*(1+CARROT_DIM_RTRN_PCT)^A47 -> 337.05812 | C47: =B47*PERMANENT_HOURLY_RATE -> 11702.658 | D47: =B47*TEMP_HOURLY_RATE -> 5851.329 | E47: =A47*CARROT_FERTILIZER_PER_BED -> 3960 | F47: =B47-B46 -> 44.758396 | G47: =C47-C46 -> 1554.0115 | H47: =D47-D46 -> 777.00575 | I47: =E47-E46 -> 440 | J47: =G47+I47 -> 1994.0115 | K47: =H47+I47 -> 1217.0058 | L47: =CARROT_REVENUE_PER_BED -> 2094 | M47: =IF(L47>=J47,1,0) -> 1 | N47: =IF(L47>=K47,1,0) -> 1 | O47: =B47*CARROT_MC_RATE -> 11702.658 | P47: =O47-O46 -> 1554.0115 | Q47: =P47+I47 -> 1994.0115 | R47: =IF(L47>=Q47,1,0) -> 1 | S47: =MIN(B47,PERMANENT_FIELD_LABOR_HOURS)*PERMANENT_HOURLY_RATE+MAX(0,B47-PERMANENT_FIELD_LABOR_HOURS)*TEMP_HOURLY_RATE -> 11702.658 | T47: =S47-S46 -> 1554.0115 | U47: =T47+I47 -> 1994.0115 | V47: =IF(L47>=U47,1,0) -> 1
A48: =ROW()-ROW($A$38) -> 10 | B48: =A48*CARROT_HRS_PER_WEEK_PER_BED*SEASON_WEEKS*(1+CARROT_DIM_RTRN_PCT)^A48 -> 383.87175 | C48: =B48*PERMANENT_HOURLY_RATE -> 13328.027 | D48: =B48*TEMP_HOURLY_RATE -> 6664.0136 | E48: =A48*CARROT_FERTILIZER_PER_BED -> 4400 | F48: =B48-B47 -> 46.813628 | G48: =C48-C47 -> 1625.3692 | H48: =D48-D47 -> 812.68459 | I48: =E48-E47 -> 440 | J48: =G48+I48 -> 2065.3692 | K48: =H48+I48 -> 1252.6846 | L48: =CARROT_REVENUE_PER_BED -> 2094 | M48: =IF(L48>=J48,1,0) -> 1 | N48: =IF(L48>=K48,1,0) -> 1 | O48: =B48*CARROT_MC_RATE -> 13328.027 | P48: =O48-O47 -> 1625.3692 | Q48: =P48+I48 -> 2065.3692 | R48: =IF(L48>=Q48,1,0) -> 1 | S48: =MIN(B48,PERMANENT_FIELD_LABOR_HOURS)*PERMANENT_HOURLY_RATE+MAX(0,B48-PERMANENT_FIELD_LABOR_HOURS)*TEMP_HOURLY_RATE -> 13328.027 | T48: =S48-S47 -> 1625.3692 | U48: =T48+I48 -> 2065.3692 | V48: =IF(L48>=U48,1,0) -> 1
A49: =ROW()-ROW($A$38) -> 11 | B49: =A49*CARROT_HRS_PER_WEEK_PER_BED*SEASON_WEEKS*(1+CARROT_DIM_RTRN_PCT)^A49 -> 432.8154 | C49: =B49*PERMANENT_HOURLY_RATE -> 15027.351 | D49: =B49*TEMP_HOURLY_RATE -> 7513.6754 | E49: =A49*CARROT_FERTILIZER_PER_BED -> 4840 | F49: =B49-B48 -> 48.943649 | G49: =C49-C48 -> 1699.3235 | H49: =D49-D48 -> 849.66174 | I49: =E49-E48 -> 440 | J49: =G49+I49 -> 2139.3235 | K49: =H49+I49 -> 1289.6617 | L49: =CARROT_REVENUE_PER_BED -> 2094 | M49: =IF(L49>=J49,1,0) -> 0 | N49: =IF(L49>=K49,1,0) -> 1 | O49: =B49*CARROT_MC_RATE -> 15027.351 | P49: =O49-O48 -> 1699.3235 | Q49: =P49+I49 -> 2139.3235 | R49: =IF(L49>=Q49,1,0) -> 0 | S49: =MIN(B49,PERMANENT_FIELD_LABOR_HOURS)*PERMANENT_HOURLY_RATE+MAX(0,B49-PERMANENT_FIELD_LABOR_HOURS)*TEMP_HOURLY_RATE -> 15027.351 | T49: =S49-S48 -> 1699.3235 | U49: =T49+I49 -> 2139.3235 | V49: =IF(L49>=U49,1,0) -> 0
A50: =ROW()-ROW($A$38) -> 12 | B50: =A50*CARROT_HRS_PER_WEEK_PER_BED*SEASON_WEEKS*(1+CARROT_DIM_RTRN_PCT)^A50 -> 483.96631 | C50: =B50*PERMANENT_HOURLY_RATE -> 16803.31 | D50: =B50*TEMP_HOURLY_RATE -> 8401.6552 | E50: =A50*CARROT_FERTILIZER_PER_BED -> 5280 | F50: =B50-B49 -> 51.150911 | G50: =C50-C49 -> 1775.9596 | H50: =D50-D49 -> 887.97982 | I50: =E50-E49 -> 440 | J50: =G50+I50 -> 2215.9596 | K50: =H50+I50 -> 1327.9798 | L50: =CARROT_REVENUE_PER_BED -> 2094 | M50: =IF(L50>=J50,1,0) -> 0 | N50: =IF(L50>=K50,1,0) -> 1 | O50: =B50*CARROT_MC_RATE -> 16803.31 | P50: =O50-O49 -> 1775.9596 | Q50: =P50+I50 -> 2215.9596 | R50: =IF(L50>=Q50,1,0) -> 0 | S50: =MIN(B50,PERMANENT_FIELD_LABOR_HOURS)*PERMANENT_HOURLY_RATE+MAX(0,B50-PERMANENT_FIELD_LABOR_HOURS)*TEMP_HOURLY_RATE -> 16803.31 | T50: =S50-S49 -> 1775.9596 | U50: =T50+I50 -> 2215.9596 | V50: =IF(L50>=U50,1,0) -> 0
... A58: =ROW()-ROW($A$38) -> 20 | B58: =A58*CARROT_HRS_PER_WEEK_PER_BED*SEASON_WEEKS*(1+CARROT_DIM_RTRN_PCT)^A58 -> 982.7766 | C58: =B58*PERMANENT_HOURLY_RATE -> 34122.003 | D58: =B58*TEMP_HOURLY_RATE -> 17061.002 | E58: =A58*CARROT_FERTILIZER_PER_BED -> 8800 | F58: =B58-B57 -> 71.910483 | G58: =C58-C57 -> 2496.732 | H58: =D58-D57 -> 1248.366 | I58: =E58-E57 -> 440 | J58: =G58+I58 -> 2936.732 | K58: =H58+I58 -> 1688.366 | L58: =CARROT_REVENUE_PER_BED -> 2094 | M58: =IF(L58>=J58,1,0) -> 0 | N58: =IF(L58>=K58,1,0) -> 1 | O58: =B58*CARROT_MC_RATE -> 34122.003 | P58: =O58-O57 -> 2496.732 | Q58: =P58+I58 -> 2936.732 | R58: =IF(L58>=Q58,1,0) -> 0 | S58: =MIN(B58,PERMANENT_FIELD_LABOR_HOURS)*PERMANENT_HOURLY_RATE+MAX(0,B58-PERMANENT_FIELD_LABOR_HOURS)*TEMP_HOURLY_RATE -> 29560.202 | T58: =S58-S57 -> 1248.366 | U58: =T58+I58 -> 1688.366 | V58: =IF(L58>=U58,1,0) -> 1
A61: Mesclun schedule | C61: LABOR_HOURS(q) = q × MESCLUN_HRS_PER_WEEK_PER_BED × SEASON_WEEKS × (1 + MESCLUN_DIM_RTRN_PCT)^q
...

Sheet Optimization
A1: Optimization - decision cells, objective, constraints, Solver setup
A2: Orange cells are the Solver changing cells. Green cells are constraint checks. Gold cells are the recommendation.
A4: Decision cells (Solver changing cells: integer, non-negative)
A5: Crop | B5: Named range | C5: Beds | D5: Unit | E5: Note
A6: Tomato | B6: TOMATO_BEDS | C6: 10 | D6: beds | E6: Solver writes this value. Checks (V1 and O5) confirm it equals the exhaustive-enumeration optimum.
A7: Carrot | B7: CARROT_BEDS | C7: 20 | D7: beds | E7: Solver writes this value. Checks (V1 and O5) confirm it equals the exhaustive-enumeration optimum.
A8: Mesclun | B8: MESCLUN_BEDS | C8: 30 | D8: beds | E8: Solver writes this value. Checks (V1 and O5) confirm it equals the exhaustive-enumeration optimum.
A10: Objective (Solver: Set Objective, Max)
A11: Seasonal profit | B11: OBJECTIVE_SEASONAL_PROFIT | C11: =SEASONAL_PROFIT -> 42775.155 | D11: $ | E11: SEASONAL_PROFIT = TOTAL_REVENUE − TOTAL_FERTILIZER − TOTAL_LABOR_COST − FIXED_SEASON_COST (Cost Structure sheet)
A13: Constraints (green = constraint-check cells)
A14: Constraint | B14: Left-hand side | C14: Relation | D14: Right-hand side | E14: Slack | F14: Check | G14: Binding?
A15: TOMATO_BEDS ≤ TOMATO_BED_CAP | B15: =TOMATO_BEDS -> 10 | C15: ≤ | D15: =TOMATO_BED_CAP -> 20 | E15: =D15-B15 -> 10 | F15: =IF(B15<=D15+0.000000001,"OK","VIOLATED") -> OK | G15: =IF(ABS(E15)<0.000000001,"Binding","Not binding") -> Not binding
A16: CARROT_BEDS ≤ CARROT_BED_CAP | B16: =CARROT_BEDS -> 20 | C16: ≤ | D16: =CARROT_BED_CAP -> 20 | E16: =D16-B16 -> 0 | F16: =IF(B16<=D16+0.000000001,"OK","VIOLATED") -> OK | G16: =IF(ABS(E16)<0.000000001,"Binding","Not binding") -> Binding
A17: MESCLUN_BEDS ≤ MESCLUN_BED_CAP | B17: =MESCLUN_BEDS -> 30 | C17: ≤ | D17: =MESCLUN_BED_CAP -> 30 | E17: =D17-B17 -> 0 | F17: =IF(B17<=D17+0.000000001,"OK","VIOLATED") -> OK | G17: =IF(ABS(E17)<0.000000001,"Binding","Not binding") -> Binding
A18: TOTAL_BEDS_USED ≤ TOTAL_BEDS_AVAILABLE | B18: =TOTAL_BEDS_USED -> 60 | C18: ≤ | D18: =TOTAL_BEDS_AVAILABLE -> 64 | E18: =D18-B18 -> 4 | F18: =IF(B18<=D18+0.000000001,"OK","VIOLATED") -> OK | G18: =IF(ABS(E18)<0.000000001,"Binding","Not binding") -> Not binding
A19: TEMP_HOURS_USED ≤ TEMP_HOURS_CAP | B19: =TEMP_HOURS_USED -> 4556.8228 | C19: ≤ | D19: =TEMP_HOURS_CAP -> 5760 | E19: =D19-B19 -> 1203.1772 | F19: =IF(B19<=D19+0.000000001,"OK","VIOLATED") -> OK | G19: =IF(ABS(E19)<0.000000001,"Binding","Not binding") -> Not binding
A20: TOTAL_LABOR_HOURS ≤ TOTAL_LABOR_HOURS_CAP | B20: =TOTAL_LABOR_HOURS -> 5276.8228 | C20: ≤ | D20: =TOTAL_LABOR_HOURS_CAP -> 6480 | E20: =D20-B20 -> 1203.1772 | F20: =IF(B20<=D20+0.000000001,"OK","VIOLATED") -> OK | G20: =IF(ABS(E20)<0.000000001,"Binding","Not binding") -> Not binding
A21: TOMATO_BEDS integer | B21: =TOMATO_BEDS -> 10 | C21: int | D21: integer | E21: — | F21: =IF(B21=INT(B21),"OK","VIOLATED") -> OK | G21: —
A22: CARROT_BEDS integer | B22: =CARROT_BEDS -> 20 | C22: int | D22: integer | E22: — | F22: =IF(B22=INT(B22),"OK","VIOLATED") -> OK | G22: —
A23: MESCLUN_BEDS integer | B23: =MESCLUN_BEDS -> 30 | C23: int | D23: integer | E23: — | F23: =IF(B23=INT(B23),"OK","VIOLATED") -> OK | G23: —
A24: TOMATO_BEDS ≥ 0 | B24: =TOMATO_BEDS -> 10 | C24: ≥ | D24: 0 | E24: =B24-D24 -> 10 | F24: =IF(B24>=D24,"OK","VIOLATED") -> OK | G24: =IF(ABS(E24)<0.000000001,"Binding","Not binding") -> Not binding
A25: CARROT_BEDS ≥ 0 | B25: =CARROT_BEDS -> 20 | C25: ≥ | D25: 0 | E25: =B25-D25 -> 20 | F25: =IF(B25>=D25,"OK","VIOLATED") -> OK | G25: =IF(ABS(E25)<0.000000001,"Binding","Not binding") -> Not binding
A26: MESCLUN_BEDS ≥ 0 | B26: =MESCLUN_BEDS -> 30 | C26: ≥ | D26: 0 | E26: =B26-D26 -> 30 | F26: =IF(B26>=D26,"OK","VIOLATED") -> OK | G26: =IF(ABS(E26)<0.000000001,"Binding","Not binding") -> Not binding
A28: Marginal analysis at the current mix: what happens if one bed is added or removed (labor priced at the farm-level permanent-first allocation)
A29: Crop | B29: Current beds | C29: Labor hours of next bed | D29: Labor cost of next bed | E29: Fertilizer of next bed | F29: Revenue of next bed (P) | G29: Profit change: +1 bed | H29: +1 bed feasible? | I29: Labor hours of last bed | J29: Profit change: −1 bed | K29: What limits this crop
A30: Tomato | B30: =TOMATO_BEDS -> 10 | C30: =((TOMATO_BEDS+1)*TOMATO_HRS_PER_WEEK_PER_BED*SEASON_WEEKS*(1+TOMATO_DIM_RTRN_PCT)^(TOMATO_BEDS+1))-TOMATO_LABOR_HRS -> 490.21732 | D30: =(MIN(TOTAL_LABOR_HOURS+C30,PERMANENT_FIELD_LABOR_HOURS)*PERMANENT_HOURLY_RATE+MAX(0,TOTAL_LABOR_HOURS+C30-PERMANENT_FIELD_LABOR_HOURS)*TEMP_HOURLY_RATE)-TOTAL_LABOR_COST -> 8510.1728 | E30: =TOMATO_FERTILIZER_PER_BED -> 880 | F30: =TOMATO_REVENUE_PER_BED -> 8800 | G30: =F30-E30-D30 -> -590.17276 | H30: =AND(TOMATO_BEDS+1<=TOMATO_BED_CAP,TOTAL_BEDS_USED+1<=TOTAL_BEDS_AVAILABLE,TOTAL_LABOR_HOURS+C30<=TOTAL_LABOR_HOURS_CAP,MAX(0,TOTAL_LABOR_HOURS+C30-PERMANENT_FIELD_LABOR_HOURS)<=TEMP_HOURS_CAP) -> TRUE | I30: =IF(TOMATO_BEDS=0,0,TOMATO_LABOR_HRS-((TOMATO_BEDS-1)*TOMATO_HRS_PER_WEEK_PER_BED*SEASON_WEEKS*(1+TOMATO_DIM_RTRN_PCT)^(TOMATO_BEDS-1))) -> 424.43058 | J30: =IF(TOMATO_BEDS=0,"n/a",-(F30-E30)+(TOTAL_LABOR_COST-(MIN(TOTAL_LABOR_HOURS-I30,PERMANENT_FIELD_LABOR_HOURS)*PERMANENT_HOURLY_RATE+MAX(0,TOTAL_LABOR_HOURS-I30-PERMANENT_FIELD_LABOR_HOURS)*TEMP_HOURLY_RATE))) -> -551.88506 | K30: =IF(TOMATO_BEDS>=TOMATO_BED_CAP,"BINDING: tomato bed cap ("&TOMATO_BED_CAP&" beds). One more bed would change profit by "&TEXT(G30,"$#,##0;-$#,##0")&", so the cap limits profit.",IF(NOT(H30),"BINDING: a farm-level bed or labor limit blocks the next tomato bed.",IF(G30<=0,"Not constraint-limited: stops on marginal cost. Bed "&(TOMATO_BEDS+1)&" would add "&TEXT(C30,"#,##0")&" labor hours and change profit by "&TEXT(G30,"$#,##0;-$#,##0")&".","NOT OPTIMAL: one more tomato bed would raise profit by "&TEXT(G30,"$#,##0")&"."))) -> Not constraint-limited: stops on marginal cost. Bed 11 would add 490 labor hours and change profit by -$590.
A31: Carrot | B31: =CARROT_BEDS -> 20 | C31: =((CARROT_BEDS+1)*CARROT_HRS_PER_WEEK_PER_BED*SEASON_WEEKS*(1+CARROT_DIM_RTRN_PCT)^(CARROT_BEDS+1))-CARROT_LABOR_HRS -> 74.936715 | D31: =(MIN(TOTAL_LABOR_HOURS+C31,PERMANENT_FIELD_LABOR_HOURS)*PERMANENT_HOURLY_RATE+MAX(0,TOTAL_LABOR_HOURS+C31-PERMANENT_FIELD_LABOR_HOURS)*TEMP_HOURLY_RATE)-TOTAL_LABOR_COST -> 1300.9014 | E31: =CARROT_FERTILIZER_PER_BED -> 440 | F31: =CARROT_REVENUE_PER_BED -> 2094 | G31: =F31-E31-D31 -> 353.09862 | H31: =AND(CARROT_BEDS+1<=CARROT_BED_CAP,TOTAL_BEDS_USED+1<=TOTAL_BEDS_AVAILABLE,TOTAL_LABOR_HOURS+C31<=TOTAL_LABOR_HOURS_CAP,MAX(0,TOTAL_LABOR_HOURS+C31-PERMANENT_FIELD_LABOR_HOURS)<=TEMP_HOURS_CAP) -> FALSE | I31: =IF(CARROT_BEDS=0,0,CARROT_LABOR_HRS-((CARROT_BEDS-1)*CARROT_HRS_PER_WEEK_PER_BED*SEASON_WEEKS*(1+CARROT_DIM_RTRN_PCT)^(CARROT_BEDS-1))) -> 71.910483 | J31: =IF(CARROT_BEDS=0,"n/a",-(F31-E31)+(TOTAL_LABOR_COST-(MIN(TOTAL_LABOR_HOURS-I31,PERMANENT_FIELD_LABOR_HOURS)*PERMANENT_HOURLY_RATE+MAX(0,TOTAL_LABOR_HOURS-I31-PERMANENT_FIELD_LABOR_HOURS)*TEMP_HOURLY_RATE))) -> -405.63402 | K31: =IF(CARROT_BEDS>=CARROT_BED_CAP,"BINDING: carrot bed cap ("&CARROT_BED_CAP&" beds). One more bed would change profit by "&TEXT(G31,"$#,##0;-$#,##0")&", so the cap limits profit.",IF(NOT(H31),"BINDING: a farm-level bed or labor limit blocks the next carrot bed.",IF(G31<=0,"Not constraint-limited: stops on marginal cost. Bed "&(CARROT_BEDS+1)&" would add "&TEXT(C31,"#,##0")&" labor hours and change profit by "&TEXT(G31,"$#,##0;-$#,##0")&".","NOT OPTIMAL: one more carrot bed would raise profit by "&TEXT(G31,"$#,##0")&"."))) -> BINDING: carrot bed cap (20 beds). One more bed would change profit by $353, so the cap limits profit.
A32: Mesclun | B32: =MESCLUN_BEDS -> 30 | C32: =((MESCLUN_BEDS+1)*MESCLUN_HRS_PER_WEEK_PER_BED*SEASON_WEEKS*(1+MESCLUN_DIM_RTRN_PCT)^(MESCLUN_BEDS+1))-MESCLUN_LABOR_HRS -> 90.635109 | D32: =(MIN(TOTAL_LABOR_HOURS+C32,PERMANENT_FIELD_LABOR_HOURS)*PERMANENT_HOURLY_RATE+MAX(0,TOTAL_LABOR_HOURS+C32-PERMANENT_FIELD_LABOR_HOURS)*TEMP_HOURLY_RATE)-TOTAL_LABOR_COST -> 1573.4255 | E32: =MESCLUN_FERTILIZER_PER_BED -> 880 | F32: =MESCLUN_REVENUE_PER_BED -> 2700 | G32: =F32-E32-D32 -> 246.5745 | H32: =AND(MESCLUN_BEDS+1<=MESCLUN_BED_CAP,TOTAL_BEDS_USED+1<=TOTAL_BEDS_AVAILABLE,TOTAL_LABOR_HOURS+C32<=TOTAL_LABOR_HOURS_CAP,MAX(0,TOTAL_LABOR_HOURS+C32-PERMANENT_FIELD_LABOR_HOURS)<=TEMP_HOURS_CAP) -> FALSE | I32: =IF(MESCLUN_BEDS=0,0,MESCLUN_LABOR_HRS-((MESCLUN_BEDS-1)*MESCLUN_HRS_PER_WEEK_PER_BED*SEASON_WEEKS*(1+MESCLUN_DIM_RTRN_PCT)^(MESCLUN_BEDS-1))) -> 88.709705 | J32: =IF(MESCLUN_BEDS=0,"n/a",-(F32-E32)+(TOTAL_LABOR_COST-(MIN(TOTAL_LABOR_HOURS-I32,PERMANENT_FIELD_LABOR_HOURS)*PERMANENT_HOURLY_RATE+MAX(0,TOTAL_LABOR_HOURS-I32-PERMANENT_FIELD_LABOR_HOURS)*TEMP_HOURLY_RATE))) -> -279.99952 | K32: =IF(MESCLUN_BEDS>=MESCLUN_BED_CAP,"BINDING: mesclun bed cap ("&MESCLUN_BED_CAP&" beds). One more bed would change profit by "&TEXT(G32,"$#,##0;-$#,##0")&", so the cap limits profit.",IF(NOT(H32),"BINDING: a farm-level bed or labor limit blocks the next mesclun bed.",IF(G32<=0,"Not constraint-limited: stops on marginal cost. Bed "&(MESCLUN_BEDS+1)&" would add "&TEXT(C32,"#,##0")&" labor hours and change profit by "&TEXT(G32,"$#,##0;-$#,##0")&".","NOT OPTIMAL: one more mesclun bed would raise profit by "&TEXT(G32,"$#,##0")&"."))) -> BINDING: mesclun bed cap (30 beds). One more bed would change profit by $247, so the cap limits profit.
A34: Farm-level constraints at the current mix
A35: Constraint | B35: Used | C35: Available | D35: Unused | E35: Statement
A36: Beds (64-bed farm) | B36: =TOTAL_BEDS_USED -> 60 | C36: =TOTAL_BEDS_AVAILABLE -> 64 | D36: =UNUSED_BEDS -> 4 | E36: =IF(D36<=0.000000001,"BINDING: all beds are used; extra beds must displace existing ones (opportunity cost).","Not binding: "&TEXT(D36,"#,##0")&" beds unused, so this limit has no opportunity cost at the current mix.") -> Not binding: 4 beds unused, so this limit has no opportunity cost at the current mix.
